<mujoco model="go1">
  <compiler angle="radian" meshdir="assets" autolimits="true"/>

  <option cone="elliptic" impratio="100"/>

  <default>
    <default class="go1">
      <geom friction="0.6" margin="0.001" condim="1"/>
      <joint axis="0 1 0" damping="2" armature="0.01" frictionloss="0.2"/>
      <position kp="100" forcerange="-23.7 23.7"/>
      <default class="abduction">
        <joint axis="1 0 0" damping="1" range="-0.863 0.863"/>
        <motor ctrlrange="-0.863 0.863"/>
      </default>
      <default class="hip">
        <joint range="-0.686 4.501"/>
        <position ctrlrange="-0.686 4.501"/>
      </default>
      <default class="knee">
        <joint range="-2.818 -0.888"/>
        <position forcerange="-35.55 35.55" ctrlrange="-2.818 -0.888"/>
      </default>

      <default class="abduction_torque">
        <joint axis="1 0 0" damping="1" range="-0.863 0.863"/>
        <motor ctrlrange="-12 12"/>
      </default>
      <default class="hip_torque">
        <joint range="-0.686 4.501"/>
        <motor ctrlrange="-12 12"/>
      </default>
      <default class="knee_torque">
        <joint range="-2.818 -0.888"/>
        <motor ctrlrange="-12 12"/>
      </default>

      <default class="visual">
        <geom type="mesh" contype="0" conaffinity="0" group="2" material="dark"/>
      </default>
      <default class="collision">
        <geom group="3" type="capsule"/>
        <default class="hip_left1">
          <geom size="0.046 0.02" pos="0 0.045 0" quat="1 1 0 0" type="cylinder"/>
        </default>
        <default class="hip_left2">
          <geom size="0.031 0.02" pos="0 0.065 0" quat="1 1 0 0" type="cylinder"/>
        </default>
        <default class="hip_left3">
          <geom size="0.046 0.02" quat="1 1 0 0" type="cylinder"/>
        </default>
        <default class="hip_right1">
          <geom size="0.046 0.02" pos="0 -0.045 0" quat="1 1 0 0" type="cylinder"/>
        </default>
        <default class="hip_right2">
          <geom size="0.031 0.02" pos="0 -0.065 0" quat="1 1 0 0" type="cylinder"/>
        </default>
        <default class="hip_right3">
          <geom size="0.046 0.02" quat="1 1 0 0" type="cylinder"/>
        </default>
        <default class="thigh1">
          <geom size="0.015" fromto="-0.02 0 0 -0.02 0 -0.16"/>
        </default>
        <default class="thigh2">
          <geom size="0.015" fromto="0 0 0 -0.02 0 -0.1"/>
        </default>
        <default class="thigh3">
          <geom size="0.015" fromto="-0.02 0 -0.16 0 0 -0.2"/>
        </default>
        <default class="calf1">
          <geom size="0.01" fromto="0 0 0 0.02 0 -0.13"/>
        </default>
        <default class="calf2">
          <geom size="0.01" fromto="0.02 0 -0.13 0 0 -0.2"/>
        </default>
        <default class="foot">
          <geom type="sphere" size="0.023" pos="0 0 -0.213" priority="1" solimp="0.015 1 0.023" condim="6"
            friction="0.8 0.02 0.01"/>
        </default>
      </default>
    </default>
  </default>

  <asset>
    <material name="dark" rgba="0.1 0.1 0.1 1"/>
    <mesh class="go1" file="trunk.stl"/>
    <mesh class="go1" file="hip.stl"/>
    <mesh class="go1" file="thigh_mirror.stl"/>
    <mesh class="go1" file="calf.stl"/>
    <mesh class="go1" file="thigh.stl"/>
  </asset>

  <worldbody>
    <light name="spotlight" mode="targetbodycom" target="trunk" pos="0 -1 2"/>
    <body name="trunk" pos="0 0 0.445" childclass="go1">
      <site name="base" pos="0 0 0" quat="1 0 0 0"/>
      <camera name="tracking" mode="trackcom" pos="0 -1 0.8" xyaxes="1 0 0 0 1 1"/>
      <site name="head" pos="0.3 0 0" rgba="1 0 0 1" size="0.02" group="5"/>
      <inertial pos="0.0223 0.002 -0.0005" mass="5.204"
        fullinertia="0.0168352186 0.0656071082 0.0742720659 0.0004636141 0.0002367952 3.6671e-05"/>
      <freejoint/>
      <geom class="visual" mesh="trunk"/>
      <geom class="collision" size="0.125 0.04 0.057" type="box"/>
      <geom class="collision" quat="1 0 1 0" pos="0 -0.04 0" size="0.058 0.125" type="cylinder"/>
      <geom class="collision" quat="1 0 1 0" pos="0 +0.04 0" size="0.058 0.125" type="cylinder"/>
      <geom class="collision" pos="0.25 0 0" size="0.005 0.06 0.05" type="box"/>
      <geom class="collision" pos="0.25 0.06 -0.01" size="0.009 0.035"/>
      <geom class="collision" pos="0.25 -0.06 -0.01" size="0.009 0.035"/>
      <geom class="collision" pos="0.25 0 -0.05" size="0.01 0.06" quat="1 1 0 0"/>
      <geom class="collision" pos="0.255 0 0.0355" size="0.021 0.052" quat="1 1 0 0"/>
      <site name="imu" pos="0 0 0"/>
      <body name="FL_hip" pos="0.1881 0.04675 0">
        <inertial pos="-0.0049166 -0.00762615 -8.865e-05" mass="0.68"
          fullinertia="0.000374268192 0.000635923669 0.000457647394 0.000036844422 -0.000000986754 -0.000001172894"/>
        <joint class="abduction_torque" name="FL_hip_joint"/>
        <geom class="visual" mesh="hip"/>
        <geom class="hip_left1"/>
        <geom class="hip_left2"/>
        <body name="FL_thigh" pos="0 0.08 0">
          <inertial pos="-0.00304722 -0.019315 -0.0305004" mass="1.009"
            fullinertia="0.005851561134 0.005596155105 0.00107157026 0.000001783284 0.000328291374 0.000021430713"/>
          <joint class="hip_torque" name="FL_thigh_joint"/>
          <geom class="visual" mesh="thigh"/>
          <geom class="thigh1"/>
          <geom class="thigh2"/>
          <geom class="thigh3"/>
          <body name="FL_calf" pos="0 0 -0.213">
            <inertial pos="0.00429862 0.000976676 -0.146197" mass="0.195862"
              fullinertia="0.000374268192 0.000635923669 0.000457647394 3.6844422e-05 -9.86754e-07 -1.172894e-06"/>
            <joint class="knee_torque" name="FL_calf_joint"/>
            <geom class="visual" mesh="calf"/>
            <geom class="calf1"/>
            <geom class="calf2"/>
            <geom name="FL" class="foot"/>
            <site name="FL" pos="0 0 -0.213" type="sphere" size="0.023" group="5"/>
          </body>
        </body>
      </body>
      <body name="RL_hip" pos="-0.1881 0.04675 0">
        <inertial pos="0.0049166 -0.00762615 -8.865e-05" mass="0.68"
          fullinertia="0.000374268192 0.000635923669 0.000457647394 0.000036844422 -0.000000986754 -0.000001172894"/>
        <joint class="abduction_torque" name="RL_hip_joint"/>
        <geom class="visual" quat="0 0 1 0" mesh="hip"/>
        <geom class="hip_left1"/>
        <geom class="hip_left2"/>
        <geom class="hip_left3"/>
        <body name="RL_thigh" pos="0 0.08 0">
          <inertial pos="-0.00304722 -0.019315 -0.0305004" mass="1.009"
            fullinertia="0.005851561134 0.005596155105 0.00107157026 0.000001783284 0.000328291374 0.000021430713"/>
          <joint class="hip_torque" name="RL_thigh_joint"/>
          <geom class="visual" mesh="thigh"/>
          <geom class="thigh1"/>
          <geom class="thigh2"/>
          <geom class="thigh3"/>
          <body name="RL_calf" pos="0 0 -0.213">
            <inertial pos="0.00429862 0.000976676 -0.146197"
              mass="0.195862" fullinertia="0.002939186297 0.00295576935 0.000030273372 0.000001440899 -0.000105359550 -0.000024397752"/>
            <joint class="knee_torque" name="RL_calf_joint"/>
            <geom class="visual" mesh="calf"/>
            <geom class="calf1"/>
            <geom class="calf2"/>
            <geom name="RL" class="foot"/>
            <site name="RL" pos="0 0 -0.213" type="sphere" size="0.023" group="5"/>
          </body>
        </body>
      </body>
      <body name="FR_hip" pos="0.1881 -0.04675 0">
        <inertial pos="-0.0049166 0.00762615 -8.865e-05" mass="0.68"
          fullinertia="0.000374268192 0.000635923669 0.000457647394 0.000036844422 -0.000000986754 -0.000001172894"/>
        <joint class="abduction_torque" name="FR_hip_joint"/>
        <geom class="visual" mesh="hip" quat="1 0 0 0"/>
        <geom class="hip_right1"/>
        <geom class="hip_right2"/>
        <body name="FR_thigh" pos="0 -0.08 0">
          <inertial pos="-0.00304722 0.019315 -0.0305004" mass="1.009"
            fullinertia="0.005851561134 0.005596155105 0.00107157026 0.000001783284 0.000328291374 0.000021430713"/>
          <joint class="hip_torque" name="FR_thigh_joint"/>
          <geom class="visual" mesh="thigh_mirror"/>
          <geom class="thigh1"/>
          <geom class="thigh2"/>
          <geom class="thigh3"/>
          <body name="FR_calf" pos="0 0 -0.213">
            <inertial pos="0.00429862 0.000976676 -0.146197"
              mass="0.195862" fullinertia="0.002939186297 0.00295576935 0.000030273372 0.000001440899 -0.000105359550 -0.000024397752"/>
            <joint class="knee_torque" name="FR_calf_joint"/>
            <geom class="visual" mesh="calf"/>
            <geom class="calf1"/>
            <geom class="calf2"/>
            <geom name="FR" class="foot"/>
            <site name="FR" pos="0 0 -0.213" type="sphere" size="0.023" group="5"/>
          </body>
        </body>
      </body>
      <body name="RR_hip" pos="-0.1881 -0.04675 0">
        <inertial pos="0.0049166 0.00762615 -8.865e-05" mass="0.68"
          fullinertia="0.000374268192 0.000635923669 0.000457647394 0.000036844422 -0.000000986754 -0.000001172894"/>
        <joint class="abduction_torque" name="RR_hip_joint"/>
        <geom class="visual" quat="0 0 0 -1" mesh="hip"/>
        <geom class="hip_right1"/>
        <geom class="hip_right2"/>
        <geom class="hip_right3"/>
        <body name="RR_thigh" pos="0 -0.08 0">
          <inertial pos="-0.00304722 0.019315 -0.0305004" mass="1.009"
            fullinertia="0.005851561134 0.005596155105 0.00107157026 0.000001783284 0.000328291374 0.000021430713"/>
          <joint class="hip_torque" name="RR_thigh_joint"/>
          <geom class="visual" mesh="thigh_mirror"/>
          <geom class="thigh1"/>
          <geom class="thigh2"/>
          <geom class="thigh3"/>
          <body name="RR_calf" pos="0 0 -0.213">
            <inertial pos="0.00429862 0.000976676 -0.146197"
              mass="0.195862" fullinertia="0.002939186297 0.00295576935 0.000030273372 0.000001440899 -0.000105359550 -0.000024397752"/>
            <joint class="knee_torque" name="RR_calf_joint"/>
            <geom class="visual" mesh="calf"/>
            <geom class="calf1"/>
            <geom class="calf2"/>
            <geom name="RR" class="foot"/>
            <site name="RR" pos="0 0 -0.213" type="sphere" size="0.023" group="5"/>
          </body>
        </body>
      </body>
    </body>
  </worldbody>

  <!-- On-Board Sensors -->
  <sensor>

    <!-- Body frame IMU -->
    <accelerometer name="imu_accel" site="base"/>
    <gyro name="imu_gyro" site="base"/>
    <framequat name="imu_quat_frame" objtype="site" objname="base"/>
    <framelinvel name="imu_lin_frame" objtype="site" objname="base"/>

    <!-- Contact Sensors -->
    <touch name="FL_contact_sensor" site="FL"/>
    <touch name="BL_contact_sensor" site="RL"/>
    <touch name="FR_contact_sensor" site="FR"/>
    <touch name="BR_contact_sensor" site="RR"/>
  </sensor>

  <!-- Actuation -> Torque control -->
  <actuator>
    <motor class="abduction_torque" name="FL_hip" joint="FL_hip_joint"/>
    <motor class="hip_torque" name="FL_thigh" joint="FL_thigh_joint"/>
    <motor class="knee_torque" name="FL_calf" joint="FL_calf_joint"/>
    <motor class="abduction_torque" name="RL_hip" joint="RL_hip_joint"/>
    <motor class="hip_torque" name="RL_thigh" joint="RL_thigh_joint"/>
    <motor class="knee_torque" name="RL_calf" joint="RL_calf_joint"/>
    <motor class="abduction_torque" name="FR_hip" joint="FR_hip_joint"/>
    <motor class="hip_torque" name="FR_thigh" joint="FR_thigh_joint"/>
    <motor class="knee_torque" name="FR_calf" joint="FR_calf_joint"/>
    <motor class="abduction_torque" name="RR_hip" joint="RR_hip_joint"/>
    <motor class="hip_torque" name="RR_thigh" joint="RR_thigh_joint"/>
    <motor class="knee_torque" name="RR_calf" joint="RR_calf_joint"/>
  </actuator>

  <keyframe>
    <key name="home" qpos="0 0 0.27 1 0 0 0 0 0.9 -1.8 0 0.9 -1.8 0 0.9 -1.8 0 0.9 -1.8"
      ctrl="0 0.9 -1.8 0 0.9 -1.8 0 0.9 -1.8 0 0.9 -1.8"/>
  </keyframe>

  <!-- <equality>
    <weld body1="trunk"/>
  </equality> -->
</mujoco>
